<!-- Author: vikash@openai.com-->
<mujoco model='tosser-v1.5'>
    <compiler inertiafromgeom='auto' angle='radian'/>

    <default>
        <joint limited='true' damping='1' armature='0'/>
        <geom contype='1' conaffinity='1' condim='3' rgba='0.8 0.6 .4 1'
        	margin="0.001" solref=".02 1" solimp=".8 .8 .01" material="geom"/>
        <motor ctrlrange='-1 1'  ctrllimited='true'/>
    </default>

    <option timestep='0.02' iterations="50" solver="PGS">
        <flag energy="enable"/>
    </option>

    <visual>
        <map fogstart="3" fogend="5" force="0.1" znear="0.1"/>
        <quality shadowsize="2048"/>
        <global offwidth="800" offheight="800"/>
    </visual>

    <asset>
		<texture type="skybox" builtin="gradient" width="128" height="128" rgb1=".4 .6 .8" 
            rgb2="0 0 0"/>  
        <texture name="texgeom" type="cube" builtin="flat" mark="cross" width="127" height="1278" 
            rgb1="0.8 0.6 0.4" rgb2="0.8 0.6 0.4" markrgb="1 1 1" random="0.01"/>  
        <texture name="texplane" type="2d" builtin="checker" rgb1=".2 .3 .4" rgb2=".1 0.15 0.2" 
            width="512" height="512"/>  

        <material name='MatPlane' reflectance='0.5' texture="texplane" texrepeat="1 1" texuniform="true"/>
        <material name='geom' texture="texgeom" texuniform="true"/>
    </asset>

	
	
    <worldbody>     
        <light directional='false' diffuse='.8 .8 .8' specular='0.3 0.3 0.3' pos='0 0 4.0' dir='0 -.15 -1'/>

		<geom name='floor' pos='0 -1 0' size='1.5 3 .125' type='plane' material="MatPlane" condim='3'/>

		<body name='obj' pos='-1 0 0.2501'>
			<geom name='obj' type='box' size='.25 .25 .25'/>
			<joint name='ballz' type='slide' axis='0 0 1' limited='false' damping='.01'/>
			<joint name='bally' type='slide' axis='0 1 0' limited='false' damping='.01'/>
			<joint name='ballx' type='slide' axis='1 0 0' limited='false' damping='.01'/>
		</body>

		<body name='obj1' pos='0 0 0.201'>
			<geom name='obj1' type='box' size='.2 .2 .2'/>
			<joint name='ballz1' type='slide' axis='0 0 1' limited='false' damping='.01'/>
			<joint name='bally1' type='slide' axis='0 1 0' limited='false' damping='.01'/>
			<joint name='ballx1' type='slide' axis='1 0 0' limited='false' damping='.01'/>
		</body>

		<body name='obj2' pos='1 0 0.101'>
			<geom name='obj2' type='box' size='.1 .1 .1'/>
			<joint name='ballz2' type='slide' axis='0 0 1' limited='false' damping='.01'/>
			<joint name='bally2' type='slide' axis='0 1 0' limited='false' damping='.01'/>
			<joint name='ballx2' type='slide' axis='1 0 0' limited='false' damping='.01'/>
		</body>

		
          
	</worldbody>

	

    <actuator>
		<general name='a1' 	gear='1 0 0 0 0 0' joint='ballz'/>
		<general name='a2' 	gear='1 0 0 0 0 0' joint='ballz1'/>
		<general name='a3' 	gear='1 0 0 0 0 0' joint='ballz2'/>
    </actuator>
	

</mujoco>
